Workbook

Sheet Partner Directory
A1: Sample Partnership LLC — Partnership Basis Workbook | 2021–2025
A2: Partner Directory & Opening Balances (01/01/2021). Blue = inputs. Green = cross-sheet links. Gold = key figures.
B4: PARTNERSHIP INFORMATION
B5: Partnership Name | C5: Sample Partnership LLC
B6: EIN | C6: XX-XXXXXXX
B7: Tax Year End | C7: December 31
B8: Basis Method | C8: Tax Basis Method (IRC §705 / Rev. Proc. 2020-13)
B9: Filing Form | C9: Form 1065
B10: Periods Covered | C10: 2021 – 2025 (5 rolling years, one tab per year)
B12: PARTNER TABLE — Opening balances = 01/01/2021
B13: # | C13: Partner Name | D13: Entity Type | E13: Opening Tax Basis (2021) | F13: Opening At-Risk (2021) | G13: Opening Recourse Share | H13: Opening Nonrecourse Share | I13: Opening QNRF Share | J13: Opening QNRF Share (§465(b)(6))
B14: 1 | C14: ABC Management LLC | D14: General Partner (GP) | E14: 0 | F14: 0 | G14: 0 | H14: 0 | I14: 0 | J14: 0
B15: 2 | C15: Partner A | D15: Individual | E15: 0 | F15: 0 | G15: 0 | H15: 0 | I15: 0 | J15: 0
B16: 3 | C16: Partner B | D16: Individual | E16: 0 | F16: 0 | G16: 0 | H16: 0 | I16: 0 | J16: 0
B17: 4 | C17: Partner C Trust | D17: Trust | E17: 0 | F17: 0 | G17: 0 | H17: 0 | I17: 0 | J17: 0
B18: 5 | C18: Partner D Trust | D18: Trust | E18: 0 | F18: 0 | G18: 0 | H18: 0 | I18: 0 | J18: 0
B20: ⚠ Opening balances must tie to prior-year K-1s or formation documents. Liability shares = each partner's allocated share (not total).

Sheet 2021
A1: Sample Partnership LLC — Tax Year 2021 (Period 1 of 5)
B2: Blue = inputs. Green = cross-sheet links. Gold = key figures. Update ownership % table (Section A) if interests changed.
B4: SECTION A | OWNERSHIP TABLE — 2021
B5: Nonrecourse liabilities allocated by Profit %. Losses allocated by Loss %. Capital % = economic ownership.
B6: Partner / Metric | C6: ABC Management LLC | D6: Partner A | E6: Partner B | F6: Partner C Trust | G6: Partner D Trust | H6: Check (= 100%?)
B7: Entity Type | C7: General Partner (GP) | D7: Individual | E7: Individual | F7: Trust | G7: Trust
B8: Status | C8: Active | D8: Active | E8: Active | F8: Active | G8: Active
B9: Capital % | C9: 0.2 | D9: 0.2 | E9: 0.2 | F9: 0.2 | G9: 0.2 | H9: =IF(ABS(SUM(C9:G9)-1)<0.0001,TEXT(SUM(C9:G9),"0.0%")&" ✓",TEXT(SUM(C9:G9),"0.0%")&" ⚠") -> 100.0% ✓
B10: Profit % | C10: 0.2 | D10: 0.2 | E10: 0.2 | F10: 0.2 | G10: 0.2 | H10: =IF(ABS(SUM(C10:G10)-1)<0.0001,TEXT(SUM(C10:G10),"0.0%")&" ✓",TEXT(SUM(C10:G10),"0.0%")&" ⚠") -> 100.0% ✓
B11: Loss % | C11: 0.2 | D11: 0.2 | E11: 0.2 | F11: 0.2 | G11: 0.2 | H11: =IF(ABS(SUM(C11:G11)-1)<0.0001,TEXT(SUM(C11:G11),"0.0%")&" ✓",TEXT(SUM(C11:G11),"0.0%")&" ⚠") -> 100.0% ✓
B13: SECTION B | TAX BASIS WORKSHEET — IRC §705 / Rev. Proc. 2020-13 — 2021
B14: K-1 box refs in each label. Lines 4 & 7 auto-linked from Section D. §704(d): losses suspended when decreases exceed basis.
B15: Line Item (K-1 Box Reference) | C15: ABC Management LLC | D15: Partner A | E15: Partner B | F15: Partner C Trust | G15: Partner D Trust | H15: Total
B17: 1. Basis at Beginning of Year | C17: ='Partner Directory'!E14 -> 0 | D17: ='Partner Directory'!E15 -> 0 | E17: ='Partner Directory'!E16 -> 0 | F17: ='Partner Directory'!E17 -> 0 | G17: ='Partner Directory'!E18 -> 0 | H17: =SUM(C17:G17) -> 0
B18: INCREASES (Lines 2–4)
B19: 2a. Cash contributions | C19: 0 | D19: 0 | E19: 0 | F19: 0 | G19: 0 | H19: =SUM(C19:G19) -> 0
B20: 2b. Property contributions (adjusted tax basis, not FMV) | C20: 0 | D20: 0 | E20: 0 | F20: 0 | G20: 0 | H20: =SUM(C20:G20) -> 0
B21: Line 3 — Distributive Share of Income / Gain (K-1)
B22: 3a. Ordinary business income (Box 1) | C22: 0 | D22: 0 | E22: 0 | F22: 0 | G22: 0 | H22: =SUM(C22:G22) -> 0
B23: 3b. Rental real estate / other net rental income (Boxes 2–3) | C23: 0 | D23: 0 | E23: 0 | F23: 0 | G23: 0 | H23: =SUM(C23:G23) -> 0
B24: 3c. Guaranteed payments — services & capital (Boxes 4a, 4b) | C24: 0 | D24: 0 | E24: 0 | F24: 0 | G24: 0 | H24: =SUM(C24:G24) -> 0
B25: 3d. Interest, dividends, royalties (Boxes 5, 6a–6c, 7) | C25: 0 | D25: 0 | E25: 0 | F25: 0 | G25: 0 | H25: =SUM(C25:G25) -> 0
B26: 3e. Net short-term capital gain (Box 8) | C26: 0 | D26: 0 | E26: 0 | F26: 0 | G26: 0 | H26: =SUM(C26:G26) -> 0
B27: 3f. Net long-term / §1250 / collectibles gain (Boxes 9a–9c) | C27: 0 | D27: 0 | E27: 0 | F27: 0 | G27: 0 | H27: =SUM(C27:G27) -> 0
B28: 3g. Net §1231 gain (Box 10) | C28: 0 | D28: 0 | E28: 0 | F28: 0 | G28: 0 | H28: =SUM(C28:G28) -> 0
B29: 3h. Other income & gain (Box 11) | C29: 0 | D29: 0 | E29: 0 | F29: 0 | G29: 0 | H29: =SUM(C29:G29) -> 0
B30: 3i. Tax-exempt income (Box 18, Code A) | C30: 0 | D30: 0 | E30: 0 | F30: 0 | G30: 0 | H30: =SUM(C30:G30) -> 0
B31: 3j. Excess depletion & other increases (Box 20T; other) | C31: 0 | D31: 0 | E31: 0 | F31: 0 | G31: 0 | H31: =SUM(C31:G31) -> 0
B32: Line 3 Total — Income / Gain Subtotal | C32: =SUM(C22:C31) -> 0 | D32: =SUM(D22:D31) -> 0 | E32: =SUM(E22:E31) -> 0 | F32: =SUM(F22:F31) -> 0 | G32: =SUM(G22:G31) -> 0 | H32: =SUM(C32:G32) -> 0
B33: Line 4 — §752 Liability Increase ← auto-linked from Section D
B34: 4. Net increase in share of partnership liabilities (§752) | C34: =MAX(0,C117) -> 0 | D34: =MAX(0,D117) -> 0 | E34: =MAX(0,E117) -> 0 | F34: =MAX(0,F117) -> 0 | G34: =MAX(0,G117) -> 0 | H34: =SUM(C34:G34) -> 0
B35: TOTAL INCREASES (2a + 2b + Line 3 + Line 4) | C35: =C19+C20+C32+C34 -> 0 | D35: =D19+D20+D32+D34 -> 0 | E35: =E19+E20+E32+E34 -> 0 | F35: =F19+F20+F32+F34 -> 0 | G35: =G19+G20+G32+G34 -> 0 | H35: =SUM(C35:G35) -> 0
B36: DECREASES (Lines 5–7)
B37: 5a. Cash distributions (Box 19, Code A) | C37: 0 | D37: 0 | E37: 0 | F37: 0 | G37: 0 | H37: =SUM(C37:G37) -> 0
B38: 5b. Property distributions (adjusted tax basis) (Box 19, Code B) | C38: 0 | D38: 0 | E38: 0 | F38: 0 | G38: 0 | H38: =SUM(C38:G38) -> 0
B39: Line 6 — Distributive Share of Deductions / Losses (K-1)
B40: 6a. Ordinary business loss (Box 1) | C40: 0 | D40: 0 | E40: 0 | F40: 0 | G40: 0 | H40: =SUM(C40:G40) -> 0
B41: 6b. Rental real estate / other net rental loss (Boxes 2–3) | C41: 0 | D41: 0 | E41: 0 | F41: 0 | G41: 0 | H41: =SUM(C41:G41) -> 0
B42: 6c. Net short-term capital loss (Box 8) | C42: 0 | D42: 0 | E42: 0 | F42: 0 | G42: 0 | H42: =SUM(C42:G42) -> 0
B43: 6d. Net long-term capital loss (Box 9a) | C43: 0 | D43: 0 | E43: 0 | F43: 0 | G43: 0 | H43: =SUM(C43:G43) -> 0
...

Sheet 2022
A1: Sample Partnership LLC — Tax Year 2022 (Period 2 of 5)
B2: Blue = inputs. Green = cross-sheet links. Gold = key figures. Update ownership % table (Section A) if interests changed.
B4: SECTION A | OWNERSHIP TABLE — 2022
B5: Nonrecourse liabilities allocated by Profit %. Losses allocated by Loss %. Capital % = economic ownership.
B6: Partner / Metric | C6: ABC Management LLC | D6: Partner A | E6: Partner B | F6: Partner C Trust | G6: Partner D Trust | H6: Check (= 100%?)
B7: Entity Type | C7: General Partner (GP) | D7: Individual | E7: Individual | F7: Trust | G7: Trust
B8: Status | C8: Active | D8: Active | E8: Active | F8: Active | G8: Active
B9: Capital % | C9: 0.2 | D9: 0.2 | E9: 0.2 | F9: 0.2 | G9: 0.2 | H9: =IF(ABS(SUM(C9:G9)-1)<0.0001,TEXT(SUM(C9:G9),"0.0%")&" ✓",TEXT(SUM(C9:G9),"0.0%")&" ⚠") -> 100.0% ✓
B10: Profit % | C10: 0.2 | D10: 0.2 | E10: 0.2 | F10: 0.2 | G10: 0.2 | H10: =IF(ABS(SUM(C10:G10)-1)<0.0001,TEXT(SUM(C10:G10),"0.0%")&" ✓",TEXT(SUM(C10:G10),"0.0%")&" ⚠") -> 100.0% ✓
B11: Loss % | C11: 0.2 | D11: 0.2 | E11: 0.2 | F11: 0.2 | G11: 0.2 | H11: =IF(ABS(SUM(C11:G11)-1)<0.0001,TEXT(SUM(C11:G11),"0.0%")&" ✓",TEXT(SUM(C11:G11),"0.0%")&" ⚠") -> 100.0% ✓
B13: SECTION B | TAX BASIS WORKSHEET — IRC §705 / Rev. Proc. 2020-13 — 2022
B14: K-1 box refs in each label. Lines 4 & 7 auto-linked from Section D. §704(d): losses suspended when decreases exceed basis.
B15: Line Item (K-1 Box Reference) | C15: ABC Management LLC | D15: Partner A | E15: Partner B | F15: Partner C Trust | G15: Partner D Trust | H15: Total
B17: 1. Basis at Beginning of Year | C17: ='2021'!C59 -> 0 | D17: ='2021'!D59 -> 0 | E17: ='2021'!E59 -> 0 | F17: ='2021'!F59 -> 0 | G17: ='2021'!G59 -> 0 | H17: =SUM(C17:G17) -> 0
B18: INCREASES (Lines 2–4)
B19: 2a. Cash contributions | C19: 0 | D19: 0 | E19: 0 | F19: 0 | G19: 0 | H19: =SUM(C19:G19) -> 0
B20: 2b. Property contributions (adjusted tax basis, not FMV) | C20: 0 | D20: 0 | E20: 0 | F20: 0 | G20: 0 | H20: =SUM(C20:G20) -> 0
B21: Line 3 — Distributive Share of Income / Gain (K-1)
B22: 3a. Ordinary business income (Box 1) | C22: 0 | D22: 0 | E22: 0 | F22: 0 | G22: 0 | H22: =SUM(C22:G22) -> 0
B23: 3b. Rental real estate / other net rental income (Boxes 2–3) | C23: 0 | D23: 0 | E23: 0 | F23: 0 | G23: 0 | H23: =SUM(C23:G23) -> 0
B24: 3c. Guaranteed payments — services & capital (Boxes 4a, 4b) | C24: 0 | D24: 0 | E24: 0 | F24: 0 | G24: 0 | H24: =SUM(C24:G24) -> 0
B25: 3d. Interest, dividends, royalties (Boxes 5, 6a–6c, 7) | C25: 0 | D25: 0 | E25: 0 | F25: 0 | G25: 0 | H25: =SUM(C25:G25) -> 0
B26: 3e. Net short-term capital gain (Box 8) | C26: 0 | D26: 0 | E26: 0 | F26: 0 | G26: 0 | H26: =SUM(C26:G26) -> 0
B27: 3f. Net long-term / §1250 / collectibles gain (Boxes 9a–9c) | C27: 0 | D27: 0 | E27: 0 | F27: 0 | G27: 0 | H27: =SUM(C27:G27) -> 0
B28: 3g. Net §1231 gain (Box 10) | C28: 0 | D28: 0 | E28: 0 | F28: 0 | G28: 0 | H28: =SUM(C28:G28) -> 0
B29: 3h. Other income & gain (Box 11) | C29: 0 | D29: 0 | E29: 0 | F29: 0 | G29: 0 | H29: =SUM(C29:G29) -> 0
B30: 3i. Tax-exempt income (Box 18, Code A) | C30: 0 | D30: 0 | E30: 0 | F30: 0 | G30: 0 | H30: =SUM(C30:G30) -> 0
B31: 3j. Excess depletion & other increases (Box 20T; other) | C31: 0 | D31: 0 | E31: 0 | F31: 0 | G31: 0 | H31: =SUM(C31:G31) -> 0
B32: Line 3 Total — Income / Gain Subtotal | C32: =SUM(C22:C31) -> 0 | D32: =SUM(D22:D31) -> 0 | E32: =SUM(E22:E31) -> 0 | F32: =SUM(F22:F31) -> 0 | G32: =SUM(G22:G31) -> 0 | H32: =SUM(C32:G32) -> 0
B33: Line 4 — §752 Liability Increase ← auto-linked from Section D
B34: 4. Net increase in share of partnership liabilities (§752) | C34: =MAX(0,C117) -> 0 | D34: =MAX(0,D117) -> 0 | E34: =MAX(0,E117) -> 0 | F34: =MAX(0,F117) -> 0 | G34: =MAX(0,G117) -> 0 | H34: =SUM(C34:G34) -> 0
B35: TOTAL INCREASES (2a + 2b + Line 3 + Line 4) | C35: =C19+C20+C32+C34 -> 0 | D35: =D19+D20+D32+D34 -> 0 | E35: =E19+E20+E32+E34 -> 0 | F35: =F19+F20+F32+F34 -> 0 | G35: =G19+G20+G32+G34 -> 0 | H35: =SUM(C35:G35) -> 0
B36: DECREASES (Lines 5–7)
B37: 5a. Cash distributions (Box 19, Code A) | C37: 0 | D37: 0 | E37: 0 | F37: 0 | G37: 0 | H37: =SUM(C37:G37) -> 0
B38: 5b. Property distributions (adjusted tax basis) (Box 19, Code B) | C38: 0 | D38: 0 | E38: 0 | F38: 0 | G38: 0 | H38: =SUM(C38:G38) -> 0
B39: Line 6 — Distributive Share of Deductions / Losses (K-1)
B40: 6a. Ordinary business loss (Box 1) | C40: 0 | D40: 0 | E40: 0 | F40: 0 | G40: 0 | H40: =SUM(C40:G40) -> 0
B41: 6b. Rental real estate / other net rental loss (Boxes 2–3) | C41: 0 | D41: 0 | E41: 0 | F41: 0 | G41: 0 | H41: =SUM(C41:G41) -> 0
B42: 6c. Net short-term capital loss (Box 8) | C42: 0 | D42: 0 | E42: 0 | F42: 0 | G42: 0 | H42: =SUM(C42:G42) -> 0
B43: 6d. Net long-term capital loss (Box 9a) | C43: 0 | D43: 0 | E43: 0 | F43: 0 | G43: 0 | H43: =SUM(C43:G43) -> 0
...

Sheet 2023
A1: Sample Partnership LLC — Tax Year 2023 (Period 3 of 5)
B2: Blue = inputs. Green = cross-sheet links. Gold = key figures. Update ownership % table (Section A) if interests changed.
B4: SECTION A | OWNERSHIP TABLE — 2023
B5: Nonrecourse liabilities allocated by Profit %. Losses allocated by Loss %. Capital % = economic ownership.
B6: Partner / Metric | C6: ABC Management LLC | D6: Partner A | E6: Partner B | F6: Partner C Trust | G6: Partner D Trust | H6: Check (= 100%?)
B7: Entity Type | C7: General Partner (GP) | D7: Individual | E7: Individual | F7: Trust | G7: Trust
B8: Status | C8: Active | D8: Active | E8: Active | F8: Active | G8: Active
B9: Capital % | C9: 0.2 | D9: 0.2 | E9: 0.2 | F9: 0.2 | G9: 0.2 | H9: =IF(ABS(SUM(C9:G9)-1)<0.0001,TEXT(SUM(C9:G9),"0.0%")&" ✓",TEXT(SUM(C9:G9),"0.0%")&" ⚠") -> 100.0% ✓
B10: Profit % | C10: 0.2 | D10: 0.2 | E10: 0.2 | F10: 0.2 | G10: 0.2 | H10: =IF(ABS(SUM(C10:G10)-1)<0.0001,TEXT(SUM(C10:G10),"0.0%")&" ✓",TEXT(SUM(C10:G10),"0.0%")&" ⚠") -> 100.0% ✓
B11: Loss % | C11: 0.2 | D11: 0.2 | E11: 0.2 | F11: 0.2 | G11: 0.2 | H11: =IF(ABS(SUM(C11:G11)-1)<0.0001,TEXT(SUM(C11:G11),"0.0%")&" ✓",TEXT(SUM(C11:G11),"0.0%")&" ⚠") -> 100.0% ✓
B13: SECTION B | TAX BASIS WORKSHEET — IRC §705 / Rev. Proc. 2020-13 — 2023
B14: K-1 box refs in each label. Lines 4 & 7 auto-linked from Section D. §704(d): losses suspended when decreases exceed basis.
B15: Line Item (K-1 Box Reference) | C15: ABC Management LLC | D15: Partner A | E15: Partner B | F15: Partner C Trust | G15: Partner D Trust | H15: Total
B17: 1. Basis at Beginning of Year | C17: ='2022'!C59 -> 0 | D17: ='2022'!D59 -> 0 | E17: ='2022'!E59 -> 0 | F17: ='2022'!F59 -> 0 | G17: ='2022'!G59 -> 0 | H17: =SUM(C17:G17) -> 0
B18: INCREASES (Lines 2–4)
B19: 2a. Cash contributions | C19: 0 | D19: 0 | E19: 0 | F19: 0 | G19: 0 | H19: =SUM(C19:G19) -> 0
B20: 2b. Property contributions (adjusted tax basis, not FMV) | C20: 0 | D20: 0 | E20: 0 | F20: 0 | G20: 0 | H20: =SUM(C20:G20) -> 0
B21: Line 3 — Distributive Share of Income / Gain (K-1)
B22: 3a. Ordinary business income (Box 1) | C22: 0 | D22: 0 | E22: 0 | F22: 0 | G22: 0 | H22: =SUM(C22:G22) -> 0
B23: 3b. Rental real estate / other net rental income (Boxes 2–3) | C23: 0 | D23: 0 | E23: 0 | F23: 0 | G23: 0 | H23: =SUM(C23:G23) -> 0
B24: 3c. Guaranteed payments — services & capital (Boxes 4a, 4b) | C24: 0 | D24: 0 | E24: 0 | F24: 0 | G24: 0 | H24: =SUM(C24:G24) -> 0
B25: 3d. Interest, dividends, royalties (Boxes 5, 6a–6c, 7) | C25: 0 | D25: 0 | E25: 0 | F25: 0 | G25: 0 | H25: =SUM(C25:G25) -> 0
B26: 3e. Net short-term capital gain (Box 8) | C26: 0 | D26: 0 | E26: 0 | F26: 0 | G26: 0 | H26: =SUM(C26:G26) -> 0
B27: 3f. Net long-term / §1250 / collectibles gain (Boxes 9a–9c) | C27: 0 | D27: 0 | E27: 0 | F27: 0 | G27: 0 | H27: =SUM(C27:G27) -> 0
B28: 3g. Net §1231 gain (Box 10) | C28: 0 | D28: 0 | E28: 0 | F28: 0 | G28: 0 | H28: =SUM(C28:G28) -> 0
B29: 3h. Other income & gain (Box 11) | C29: 0 | D29: 0 | E29: 0 | F29: 0 | G29: 0 | H29: =SUM(C29:G29) -> 0
B30: 3i. Tax-exempt income (Box 18, Code A) | C30: 0 | D30: 0 | E30: 0 | F30: 0 | G30: 0 | H30: =SUM(C30:G30) -> 0
B31: 3j. Excess depletion & other increases (Box 20T; other) | C31: 0 | D31: 0 | E31: 0 | F31: 0 | G31: 0 | H31: =SUM(C31:G31) -> 0
B32: Line 3 Total — Income / Gain Subtotal | C32: =SUM(C22:C31) -> 0 | D32: =SUM(D22:D31) -> 0 | E32: =SUM(E22:E31) -> 0 | F32: =SUM(F22:F31) -> 0 | G32: =SUM(G22:G31) -> 0 | H32: =SUM(C32:G32) -> 0
B33: Line 4 — §752 Liability Increase ← auto-linked from Section D
B34: 4. Net increase in share of partnership liabilities (§752) | C34: =MAX(0,C117) -> 0 | D34: =MAX(0,D117) -> 0 | E34: =MAX(0,E117) -> 0 | F34: =MAX(0,F117) -> 0 | G34: =MAX(0,G117) -> 0 | H34: =SUM(C34:G34) -> 0
B35: TOTAL INCREASES (2a + 2b + Line 3 + Line 4) | C35: =C19+C20+C32+C34 -> 0 | D35: =D19+D20+D32+D34 -> 0 | E35: =E19+E20+E32+E34 -> 0 | F35: =F19+F20+F32+F34 -> 0 | G35: =G19+G20+G32+G34 -> 0 | H35: =SUM(C35:G35) -> 0
B36: DECREASES (Lines 5–7)
B37: 5a. Cash distributions (Box 19, Code A) | C37: 0 | D37: 0 | E37: 0 | F37: 0 | G37: 0 | H37: =SUM(C37:G37) -> 0
B38: 5b. Property distributions (adjusted tax basis) (Box 19, Code B) | C38: 0 | D38: 0 | E38: 0 | F38: 0 | G38: 0 | H38: =SUM(C38:G38) -> 0
B39: Line 6 — Distributive Share of Deductions / Losses (K-1)
B40: 6a. Ordinary business loss (Box 1) | C40: 0 | D40: 0 | E40: 0 | F40: 0 | G40: 0 | H40: =SUM(C40:G40) -> 0
B41: 6b. Rental real estate / other net rental loss (Boxes 2–3) | C41: 0 | D41: 0 | E41: 0 | F41: 0 | G41: 0 | H41: =SUM(C41:G41) -> 0
B42: 6c. Net short-term capital loss (Box 8) | C42: 0 | D42: 0 | E42: 0 | F42: 0 | G42: 0 | H42: =SUM(C42:G42) -> 0
B43: 6d. Net long-term capital loss (Box 9a) | C43: 0 | D43: 0 | E43: 0 | F43: 0 | G43: 0 | H43: =SUM(C43:G43) -> 0
...

Sheet 2024
A1: Sample Partnership LLC — Tax Year 2024 (Period 4 of 5)
B2: Blue = inputs. Green = cross-sheet links. Gold = key figures. Update ownership % table (Section A) if interests changed.
B4: SECTION A | OWNERSHIP TABLE — 2024
B5: Nonrecourse liabilities allocated by Profit %. Losses allocated by Loss %. Capital % = economic ownership.
B6: Partner / Metric | C6: ABC Management LLC | D6: Partner A | E6: Partner B | F6: Partner C Trust | G6: Partner D Trust | H6: Check (= 100%?)
B7: Entity Type | C7: General Partner (GP) | D7: Individual | E7: Individual | F7: Trust | G7: Trust
B8: Status | C8: Active | D8: Active | E8: Active | F8: Active | G8: Active
B9: Capital % | C9: 0.2 | D9: 0.2 | E9: 0.2 | F9: 0.2 | G9: 0.2 | H9: =IF(ABS(SUM(C9:G9)-1)<0.0001,TEXT(SUM(C9:G9),"0.0%")&" ✓",TEXT(SUM(C9:G9),"0.0%")&" ⚠") -> 100.0% ✓
B10: Profit % | C10: 0.2 | D10: 0.2 | E10: 0.2 | F10: 0.2 | G10: 0.2 | H10: =IF(ABS(SUM(C10:G10)-1)<0.0001,TEXT(SUM(C10:G10),"0.0%")&" ✓",TEXT(SUM(C10:G10),"0.0%")&" ⚠") -> 100.0% ✓
B11: Loss % | C11: 0.2 | D11: 0.2 | E11: 0.2 | F11: 0.2 | G11: 0.2 | H11: =IF(ABS(SUM(C11:G11)-1)<0.0001,TEXT(SUM(C11:G11),"0.0%")&" ✓",TEXT(SUM(C11:G11),"0.0%")&" ⚠") -> 100.0% ✓
B13: SECTION B | TAX BASIS WORKSHEET — IRC §705 / Rev. Proc. 2020-13 — 2024
B14: K-1 box refs in each label. Lines 4 & 7 auto-linked from Section D. §704(d): losses suspended when decreases exceed basis.
B15: Line Item (K-1 Box Reference) | C15: ABC Management LLC | D15: Partner A | E15: Partner B | F15: Partner C Trust | G15: Partner D Trust | H15: Total
B17: 1. Basis at Beginning of Year | C17: ='2023'!C59 -> 0 | D17: ='2023'!D59 -> 0 | E17: ='2023'!E59 -> 0 | F17: ='2023'!F59 -> 0 | G17: ='2023'!G59 -> 0 | H17: =SUM(C17:G17) -> 0
B18: INCREASES (Lines 2–4)
B19: 2a. Cash contributions | C19: 0 | D19: 0 | E19: 0 | F19: 0 | G19: 0 | H19: =SUM(C19:G19) -> 0
B20: 2b. Property contributions (adjusted tax basis, not FMV) | C20: 0 | D20: 0 | E20: 0 | F20: 0 | G20: 0 | H20: =SUM(C20:G20) -> 0
B21: Line 3 — Distributive Share of Income / Gain (K-1)
B22: 3a. Ordinary business income (Box 1) | C22: 0 | D22: 0 | E22: 0 | F22: 0 | G22: 0 | H22: =SUM(C22:G22) -> 0
B23: 3b. Rental real estate / other net rental income (Boxes 2–3) | C23: 0 | D23: 0 | E23: 0 | F23: 0 | G23: 0 | H23: =SUM(C23:G23) -> 0
B24: 3c. Guaranteed payments — services & capital (Boxes 4a, 4b) | C24: 0 | D24: 0 | E24: 0 | F24: 0 | G24: 0 | H24: =SUM(C24:G24) -> 0
B25: 3d. Interest, dividends, royalties (Boxes 5, 6a–6c, 7) | C25: 0 | D25: 0 | E25: 0 | F25: 0 | G25: 0 | H25: =SUM(C25:G25) -> 0
B26: 3e. Net short-term capital gain (Box 8) | C26: 0 | D26: 0 | E26: 0 | F26: 0 | G26: 0 | H26: =SUM(C26:G26) -> 0
B27: 3f. Net long-term / §1250 / collectibles gain (Boxes 9a–9c) | C27: 0 | D27: 0 | E27: 0 | F27: 0 | G27: 0 | H27: =SUM(C27:G27) -> 0
B28: 3g. Net §1231 gain (Box 10) | C28: 0 | D28: 0 | E28: 0 | F28: 0 | G28: 0 | H28: =SUM(C28:G28) -> 0
B29: 3h. Other income & gain (Box 11) | C29: 0 | D29: 0 | E29: 0 | F29: 0 | G29: 0 | H29: =SUM(C29:G29) -> 0
B30: 3i. Tax-exempt income (Box 18, Code A) | C30: 0 | D30: 0 | E30: 0 | F30: 0 | G30: 0 | H30: =SUM(C30:G30) -> 0
B31: 3j. Excess depletion & other increases (Box 20T; other) | C31: 0 | D31: 0 | E31: 0 | F31: 0 | G31: 0 | H31: =SUM(C31:G31) -> 0
B32: Line 3 Total — Income / Gain Subtotal | C32: =SUM(C22:C31) -> 0 | D32: =SUM(D22:D31) -> 0 | E32: =SUM(E22:E31) -> 0 | F32: =SUM(F22:F31) -> 0 | G32: =SUM(G22:G31) -> 0 | H32: =SUM(C32:G32) -> 0
B33: Line 4 — §752 Liability Increase ← auto-linked from Section D
B34: 4. Net increase in share of partnership liabilities (§752) | C34: =MAX(0,C117) -> 0 | D34: =MAX(0,D117) -> 0 | E34: =MAX(0,E117) -> 0 | F34: =MAX(0,F117) -> 0 | G34: =MAX(0,G117) -> 0 | H34: =SUM(C34:G34) -> 0
B35: TOTAL INCREASES (2a + 2b + Line 3 + Line 4) | C35: =C19+C20+C32+C34 -> 0 | D35: =D19+D20+D32+D34 -> 0 | E35: =E19+E20+E32+E34 -> 0 | F35: =F19+F20+F32+F34 -> 0 | G35: =G19+G20+G32+G34 -> 0 | H35: =SUM(C35:G35) -> 0
B36: DECREASES (Lines 5–7)
B37: 5a. Cash distributions (Box 19, Code A) | C37: 0 | D37: 0 | E37: 0 | F37: 0 | G37: 0 | H37: =SUM(C37:G37) -> 0
B38: 5b. Property distributions (adjusted tax basis) (Box 19, Code B) | C38: 0 | D38: 0 | E38: 0 | F38: 0 | G38: 0 | H38: =SUM(C38:G38) -> 0
B39: Line 6 — Distributive Share of Deductions / Losses (K-1)
B40: 6a. Ordinary business loss (Box 1) | C40: 0 | D40: 0 | E40: 0 | F40: 0 | G40: 0 | H40: =SUM(C40:G40) -> 0
B41: 6b. Rental real estate / other net rental loss (Boxes 2–3) | C41: 0 | D41: 0 | E41: 0 | F41: 0 | G41: 0 | H41: =SUM(C41:G41) -> 0
B42: 6c. Net short-term capital loss (Box 8) | C42: 0 | D42: 0 | E42: 0 | F42: 0 | G42: 0 | H42: =SUM(C42:G42) -> 0
B43: 6d. Net long-term capital loss (Box 9a) | C43: 0 | D43: 0 | E43: 0 | F43: 0 | G43: 0 | H43: =SUM(C43:G43) -> 0
...

Sheet 2025
A1: Sample Partnership LLC — Tax Year 2025 (Period 5 of 5)
B2: Blue = inputs. Green = cross-sheet links. Gold = key figures. Update ownership % table (Section A) if interests changed.
B4: SECTION A | OWNERSHIP TABLE — 2025
B5: Nonrecourse liabilities allocated by Profit %. Losses allocated by Loss %. Capital % = economic ownership.
B6: Partner / Metric | C6: ABC Management LLC | D6: Partner A | E6: Partner B | F6: Partner C Trust | G6: Partner D Trust | H6: Check (= 100%?)
B7: Entity Type | C7: General Partner (GP) | D7: Individual | E7: Individual | F7: Trust | G7: Trust
B8: Status | C8: Active | D8: Active | E8: Active | F8: Active | G8: Active
B9: Capital % | C9: 0.2 | D9: 0.2 | E9: 0.2 | F9: 0.2 | G9: 0.2 | H9: =IF(ABS(SUM(C9:G9)-1)<0.0001,TEXT(SUM(C9:G9),"0.0%")&" ✓",TEXT(SUM(C9:G9),"0.0%")&" ⚠") -> 100.0% ✓
B10: Profit % | C10: 0.2 | D10: 0.2 | E10: 0.2 | F10: 0.2 | G10: 0.2 | H10: =IF(ABS(SUM(C10:G10)-1)<0.0001,TEXT(SUM(C10:G10),"0.0%")&" ✓",TEXT(SUM(C10:G10),"0.0%")&" ⚠") -> 100.0% ✓
B11: Loss % | C11: 0.2 | D11: 0.2 | E11: 0.2 | F11: 0.2 | G11: 0.2 | H11: =IF(ABS(SUM(C11:G11)-1)<0.0001,TEXT(SUM(C11:G11),"0.0%")&" ✓",TEXT(SUM(C11:G11),"0.0%")&" ⚠") -> 100.0% ✓
B13: SECTION B | TAX BASIS WORKSHEET — IRC §705 / Rev. Proc. 2020-13 — 2025
B14: K-1 box refs in each label. Lines 4 & 7 auto-linked from Section D. §704(d): losses suspended when decreases exceed basis.
B15: Line Item (K-1 Box Reference) | C15: ABC Management LLC | D15: Partner A | E15: Partner B | F15: Partner C Trust | G15: Partner D Trust | H15: Total
B17: 1. Basis at Beginning of Year | C17: ='2024'!C59 -> 0 | D17: ='2024'!D59 -> 0 | E17: ='2024'!E59 -> 0 | F17: ='2024'!F59 -> 0 | G17: ='2024'!G59 -> 0 | H17: =SUM(C17:G17) -> 0
B18: INCREASES (Lines 2–4)
B19: 2a. Cash contributions | C19: 0 | D19: 0 | E19: 0 | F19: 0 | G19: 0 | H19: =SUM(C19:G19) -> 0
B20: 2b. Property contributions (adjusted tax basis, not FMV) | C20: 0 | D20: 0 | E20: 0 | F20: 0 | G20: 0 | H20: =SUM(C20:G20) -> 0
B21: Line 3 — Distributive Share of Income / Gain (K-1)
B22: 3a. Ordinary business income (Box 1) | C22: 0 | D22: 0 | E22: 0 | F22: 0 | G22: 0 | H22: =SUM(C22:G22) -> 0
B23: 3b. Rental real estate / other net rental income (Boxes 2–3) | C23: 0 | D23: 0 | E23: 0 | F23: 0 | G23: 0 | H23: =SUM(C23:G23) -> 0
B24: 3c. Guaranteed payments — services & capital (Boxes 4a, 4b) | C24: 0 | D24: 0 | E24: 0 | F24: 0 | G24: 0 | H24: =SUM(C24:G24) -> 0
B25: 3d. Interest, dividends, royalties (Boxes 5, 6a–6c, 7) | C25: 0 | D25: 0 | E25: 0 | F25: 0 | G25: 0 | H25: =SUM(C25:G25) -> 0
B26: 3e. Net short-term capital gain (Box 8) | C26: 0 | D26: 0 | E26: 0 | F26: 0 | G26: 0 | H26: =SUM(C26:G26) -> 0
B27: 3f. Net long-term / §1250 / collectibles gain (Boxes 9a–9c) | C27: 0 | D27: 0 | E27: 0 | F27: 0 | G27: 0 | H27: =SUM(C27:G27) -> 0
B28: 3g. Net §1231 gain (Box 10) | C28: 0 | D28: 0 | E28: 0 | F28: 0 | G28: 0 | H28: =SUM(C28:G28) -> 0
B29: 3h. Other income & gain (Box 11) | C29: 0 | D29: 0 | E29: 0 | F29: 0 | G29: 0 | H29: =SUM(C29:G29) -> 0
B30: 3i. Tax-exempt income (Box 18, Code A) | C30: 0 | D30: 0 | E30: 0 | F30: 0 | G30: 0 | H30: =SUM(C30:G30) -> 0
B31: 3j. Excess depletion & other increases (Box 20T; other) | C31: 0 | D31: 0 | E31: 0 | F31: 0 | G31: 0 | H31: =SUM(C31:G31) -> 0
B32: Line 3 Total — Income / Gain Subtotal | C32: =SUM(C22:C31) -> 0 | D32: =SUM(D22:D31) -> 0 | E32: =SUM(E22:E31) -> 0 | F32: =SUM(F22:F31) -> 0 | G32: =SUM(G22:G31) -> 0 | H32: =SUM(C32:G32) -> 0
B33: Line 4 — §752 Liability Increase ← auto-linked from Section D
B34: 4. Net increase in share of partnership liabilities (§752) | C34: =MAX(0,C117) -> 0 | D34: =MAX(0,D117) -> 0 | E34: =MAX(0,E117) -> 0 | F34: =MAX(0,F117) -> 0 | G34: =MAX(0,G117) -> 0 | H34: =SUM(C34:G34) -> 0
B35: TOTAL INCREASES (2a + 2b + Line 3 + Line 4) | C35: =C19+C20+C32+C34 -> 0 | D35: =D19+D20+D32+D34 -> 0 | E35: =E19+E20+E32+E34 -> 0 | F35: =F19+F20+F32+F34 -> 0 | G35: =G19+G20+G32+G34 -> 0 | H35: =SUM(C35:G35) -> 0
B36: DECREASES (Lines 5–7)
B37: 5a. Cash distributions (Box 19, Code A) | C37: 0 | D37: 0 | E37: 0 | F37: 0 | G37: 0 | H37: =SUM(C37:G37) -> 0
B38: 5b. Property distributions (adjusted tax basis) (Box 19, Code B) | C38: 0 | D38: 0 | E38: 0 | F38: 0 | G38: 0 | H38: =SUM(C38:G38) -> 0
B39: Line 6 — Distributive Share of Deductions / Losses (K-1)
B40: 6a. Ordinary business loss (Box 1) | C40: 0 | D40: 0 | E40: 0 | F40: 0 | G40: 0 | H40: =SUM(C40:G40) -> 0
B41: 6b. Rental real estate / other net rental loss (Boxes 2–3) | C41: 0 | D41: 0 | E41: 0 | F41: 0 | G41: 0 | H41: =SUM(C41:G41) -> 0
B42: 6c. Net short-term capital loss (Box 8) | C42: 0 | D42: 0 | E42: 0 | F42: 0 | G42: 0 | H42: =SUM(C42:G42) -> 0
B43: 6d. Net long-term capital loss (Box 9a) | C43: 0 | D43: 0 | E43: 0 | F43: 0 | G43: 0 | H43: =SUM(C43:G43) -> 0
...

Sheet Summary
A1: Sample Partnership LLC — Summary Dashboard | 2021–2025
B2: Auto-populated from each year tab.
B4: Metric | C4: ABC Management LLC | D4: Partner A | E4: Partner B | F4: Partner C Trust | G4: Partner D Trust | H4: Total
B6: 2021 — Period 1 of 5
B7: Ending Tax Basis (§705, Line 10) | C7: ='2021'!C59 -> 0 | D7: ='2021'!D59 -> 0 | E7: ='2021'!E59 -> 0 | F7: ='2021'!F59 -> 0 | G7: ='2021'!G59 -> 0 | H7: =SUM(C7:G7) -> 0
B8: Ending At-Risk (§465, Line 6) | C8: ='2021'!C86 -> 0 | D8: ='2021'!D86 -> 0 | E8: ='2021'!E86 -> 0 | F8: ='2021'!F86 -> 0 | G8: ='2021'!G86 -> 0 | H8: =SUM(C8:G8) -> 0
B9: Effective Loss Limit (MIN of Basis & At-Risk) | C9: =MIN('2021'!C59,'2021'!C86) -> 0 | D9: =MIN('2021'!D59,'2021'!D86) -> 0 | E9: =MIN('2021'!E59,'2021'!E86) -> 0 | F9: =MIN('2021'!F59,'2021'!F86) -> 0 | G9: =MIN('2021'!G59,'2021'!G86) -> 0 | H9: =SUM(C9:G9) -> 0
B10: Net §752 Liability Change | C10: ='2021'!C117 -> 0 | D10: ='2021'!D117 -> 0 | E10: ='2021'!E117 -> 0 | F10: ='2021'!F117 -> 0 | G10: ='2021'!G117 -> 0 | H10: =SUM(C10:G10) -> 0
B11: Capital % | C11: ='2021'!C9 -> 0.2 | D11: ='2021'!D9 -> 0.2 | E11: ='2021'!E9 -> 0.2 | F11: ='2021'!F9 -> 0.2 | G11: ='2021'!G9 -> 0.2 | H11: =SUM(C11:G11) -> 1
B13: 2022 — Period 2 of 5
B14: Ending Tax Basis (§705, Line 10) | C14: ='2022'!C59 -> 0 | D14: ='2022'!D59 -> 0 | E14: ='2022'!E59 -> 0 | F14: ='2022'!F59 -> 0 | G14: ='2022'!G59 -> 0 | H14: =SUM(C14:G14) -> 0
B15: Ending At-Risk (§465, Line 6) | C15: ='2022'!C86 -> 0 | D15: ='2022'!D86 -> 0 | E15: ='2022'!E86 -> 0 | F15: ='2022'!F86 -> 0 | G15: ='2022'!G86 -> 0 | H15: =SUM(C15:G15) -> 0
B16: Effective Loss Limit (MIN of Basis & At-Risk) | C16: =MIN('2022'!C59,'2022'!C86) -> 0 | D16: =MIN('2022'!D59,'2022'!D86) -> 0 | E16: =MIN('2022'!E59,'2022'!E86) -> 0 | F16: =MIN('2022'!F59,'2022'!F86) -> 0 | G16: =MIN('2022'!G59,'2022'!G86) -> 0 | H16: =SUM(C16:G16) -> 0
B17: Net §752 Liability Change | C17: ='2022'!C117 -> 0 | D17: ='2022'!D117 -> 0 | E17: ='2022'!E117 -> 0 | F17: ='2022'!F117 -> 0 | G17: ='2022'!G117 -> 0 | H17: =SUM(C17:G17) -> 0
B18: Capital % | C18: ='2022'!C9 -> 0.2 | D18: ='2022'!D9 -> 0.2 | E18: ='2022'!E9 -> 0.2 | F18: ='2022'!F9 -> 0.2 | G18: ='2022'!G9 -> 0.2 | H18: =SUM(C18:G18) -> 1
B20: 2023 — Period 3 of 5
B21: Ending Tax Basis (§705, Line 10) | C21: ='2023'!C59 -> 0 | D21: ='2023'!D59 -> 0 | E21: ='2023'!E59 -> 0 | F21: ='2023'!F59 -> 0 | G21: ='2023'!G59 -> 0 | H21: =SUM(C21:G21) -> 0
B22: Ending At-Risk (§465, Line 6) | C22: ='2023'!C86 -> 0 | D22: ='2023'!D86 -> 0 | E22: ='2023'!E86 -> 0 | F22: ='2023'!F86 -> 0 | G22: ='2023'!G86 -> 0 | H22: =SUM(C22:G22) -> 0
B23: Effective Loss Limit (MIN of Basis & At-Risk) | C23: =MIN('2023'!C59,'2023'!C86) -> 0 | D23: =MIN('2023'!D59,'2023'!D86) -> 0 | E23: =MIN('2023'!E59,'2023'!E86) -> 0 | F23: =MIN('2023'!F59,'2023'!F86) -> 0 | G23: =MIN('2023'!G59,'2023'!G86) -> 0 | H23: =SUM(C23:G23) -> 0
B24: Net §752 Liability Change | C24: ='2023'!C117 -> 0 | D24: ='2023'!D117 -> 0 | E24: ='2023'!E117 -> 0 | F24: ='2023'!F117 -> 0 | G24: ='2023'!G117 -> 0 | H24: =SUM(C24:G24) -> 0
B25: Capital % | C25: ='2023'!C9 -> 0.2 | D25: ='2023'!D9 -> 0.2 | E25: ='2023'!E9 -> 0.2 | F25: ='2023'!F9 -> 0.2 | G25: ='2023'!G9 -> 0.2 | H25: =SUM(C25:G25) -> 1
B27: 2024 — Period 4 of 5
B28: Ending Tax Basis (§705, Line 10) | C28: ='2024'!C59 -> 0 | D28: ='2024'!D59 -> 0 | E28: ='2024'!E59 -> 0 | F28: ='2024'!F59 -> 0 | G28: ='2024'!G59 -> 0 | H28: =SUM(C28:G28) -> 0
B29: Ending At-Risk (§465, Line 6) | C29: ='2024'!C86 -> 0 | D29: ='2024'!D86 -> 0 | E29: ='2024'!E86 -> 0 | F29: ='2024'!F86 -> 0 | G29: ='2024'!G86 -> 0 | H29: =SUM(C29:G29) -> 0
B30: Effective Loss Limit (MIN of Basis & At-Risk) | C30: =MIN('2024'!C59,'2024'!C86) -> 0 | D30: =MIN('2024'!D59,'2024'!D86) -> 0 | E30: =MIN('2024'!E59,'2024'!E86) -> 0 | F30: =MIN('2024'!F59,'2024'!F86) -> 0 | G30: =MIN('2024'!G59,'2024'!G86) -> 0 | H30: =SUM(C30:G30) -> 0
B31: Net §752 Liability Change | C31: ='2024'!C117 -> 0 | D31: ='2024'!D117 -> 0 | E31: ='2024'!E117 -> 0 | F31: ='2024'!F117 -> 0 | G31: ='2024'!G117 -> 0 | H31: =SUM(C31:G31) -> 0
B32: Capital % | C32: ='2024'!C9 -> 0.2 | D32: ='2024'!D9 -> 0.2 | E32: ='2024'!E9 -> 0.2 | F32: ='2024'!F9 -> 0.2 | G32: ='2024'!G9 -> 0.2 | H32: =SUM(C32:G32) -> 1
B34: 2025 — Period 5 of 5
B35: Ending Tax Basis (§705, Line 10) | C35: ='2025'!C59 -> 0 | D35: ='2025'!D59 -> 0 | E35: ='2025'!E59 -> 0 | F35: ='2025'!F59 -> 0 | G35: ='2025'!G59 -> 0 | H35: =SUM(C35:G35) -> 0
B36: Ending At-Risk (§465, Line 6) | C36: ='2025'!C86 -> 0 | D36: ='2025'!D86 -> 0 | E36: ='2025'!E86 -> 0 | F36: ='2025'!F86 -> 0 | G36: ='2025'!G86 -> 0 | H36: =SUM(C36:G36) -> 0
B37: Effective Loss Limit (MIN of Basis & At-Risk) | C37: =MIN('2025'!C59,'2025'!C86) -> 0 | D37: =MIN('2025'!D59,'2025'!D86) -> 0 | E37: =MIN('2025'!E59,'2025'!E86) -> 0 | F37: =MIN('2025'!F59,'2025'!F86) -> 0 | G37: =MIN('2025'!G59,'2025'!G86) -> 0 | H37: =SUM(C37:G37) -> 0
B38: Net §752 Liability Change | C38: ='2025'!C117 -> 0 | D38: ='2025'!D117 -> 0 | E38: ='2025'!E117 -> 0 | F38: ='2025'!F117 -> 0 | G38: ='2025'!G117 -> 0 | H38: =SUM(C38:G38) -> 0
B39: Capital % | C39: ='2025'!C9 -> 0.2 | D39: ='2025'!D9 -> 0.2 | E39: ='2025'!E9 -> 0.2 | F39: ='2025'!F9 -> 0.2 | G39: ='2025'!G9 -> 0.2 | H39: =SUM(C39:G39) -> 1
B41: DISCLAIMER: Template only — not tax advice. Verify all K-1 allocations before entry. Consult a qualified tax advisor.
